<?xml version="1.0" ?>
<!-- =================================================================================== -->
<!-- |    This document was autogenerated by xacro from /home/mk/catkin_ws/src/mk_description/urdf/mk.xacro | -->
<!-- |    EDITING THIS FILE BY HAND IS NOT RECOMMENDED                                 | -->
<!-- =================================================================================== -->
<robot name="mk">
    <material name="silver">
        <color rgba="0.700 0.700 0.700 1.000" />
    </material>
    <transmission name="joint1_tran">
        <type>transmission_interface/SimpleTransmission</type>
        <joint name="joint1">
            <hardwareInterface>hardware_interface/EffortJointInterface</hardwareInterface>
        </joint>
        <actuator name="joint1_actr">
            <hardwareInterface>hardware_interface/EffortJointInterface</hardwareInterface>
            <mechanicalReduction>1</mechanicalReduction>
        </actuator>
    </transmission>
    <transmission name="joint2_tran">
        <type>transmission_interface/SimpleTransmission</type>
        <joint name="joint2">
            <hardwareInterface>hardware_interface/EffortJointInterface</hardwareInterface>
        </joint>
        <actuator name="joint2_actr">
            <hardwareInterface>hardware_interface/EffortJointInterface</hardwareInterface>
            <mechanicalReduction>1</mechanicalReduction>
        </actuator>
    </transmission>
    <transmission name="joint3_tran">
        <type>transmission_interface/SimpleTransmission</type>
        <joint name="joint3">
            <hardwareInterface>hardware_interface/EffortJointInterface</hardwareInterface>
        </joint>
        <actuator name="joint3_actr">
            <hardwareInterface>hardware_interface/EffortJointInterface</hardwareInterface>
            <mechanicalReduction>1</mechanicalReduction>
        </actuator>
    </transmission>
    <transmission name="joint4_tran">
        <type>transmission_interface/SimpleTransmission</type>
        <joint name="joint4">
            <hardwareInterface>hardware_interface/EffortJointInterface</hardwareInterface>
        </joint>
        <actuator name="joint4_actr">
            <hardwareInterface>hardware_interface/EffortJointInterface</hardwareInterface>
            <mechanicalReduction>1</mechanicalReduction>
        </actuator>
    </transmission>
    <transmission name="joint5_tran">
        <type>transmission_interface/SimpleTransmission</type>
        <joint name="joint5">
            <hardwareInterface>hardware_interface/EffortJointInterface</hardwareInterface>
        </joint>
        <actuator name="joint5_actr">
            <hardwareInterface>hardware_interface/EffortJointInterface</hardwareInterface>
            <mechanicalReduction>1</mechanicalReduction>
        </actuator>
    </transmission>
    <transmission name="joint6_tran">
        <type>transmission_interface/SimpleTransmission</type>
        <joint name="joint6">
            <hardwareInterface>hardware_interface/EffortJointInterface</hardwareInterface>
        </joint>
        <actuator name="joint6_actr">
            <hardwareInterface>hardware_interface/EffortJointInterface</hardwareInterface>
            <mechanicalReduction>1</mechanicalReduction>
        </actuator>
    </transmission>
    <transmission name="joint_index_RT_tran">
        <type>transmission_interface/SimpleTransmission</type>
        <joint name="joint_index_RT">
            <hardwareInterface>hardware_interface/EffortJointInterface</hardwareInterface>
        </joint>
        <actuator name="joint_index_RT_actr">
            <hardwareInterface>hardware_interface/EffortJointInterface</hardwareInterface>
            <mechanicalReduction>1</mechanicalReduction>
        </actuator>
    </transmission>
    <transmission name="joint_middle_RT_tran">
        <type>transmission_interface/SimpleTransmission</type>
        <joint name="joint_middle_RT">
            <hardwareInterface>hardware_interface/EffortJointInterface</hardwareInterface>
        </joint>
        <actuator name="joint_middle_RT_actr">
            <hardwareInterface>hardware_interface/EffortJointInterface</hardwareInterface>
            <mechanicalReduction>1</mechanicalReduction>
        </actuator>
    </transmission>
    <transmission name="joint_ring_RT_tran">
        <type>transmission_interface/SimpleTransmission</type>
        <joint name="joint_ring_RT">
            <hardwareInterface>hardware_interface/EffortJointInterface</hardwareInterface>
        </joint>
        <actuator name="joint_ring_RT_actr">
            <hardwareInterface>hardware_interface/EffortJointInterface</hardwareInterface>
            <mechanicalReduction>1</mechanicalReduction>
        </actuator>
    </transmission>
    <transmission name="joint_pinky_RT_tran">
        <type>transmission_interface/SimpleTransmission</type>
        <joint name="joint_pinky_RT">
            <hardwareInterface>hardware_interface/EffortJointInterface</hardwareInterface>
        </joint>
        <actuator name="joint_pinky_RT_actr">
            <hardwareInterface>hardware_interface/EffortJointInterface</hardwareInterface>
            <mechanicalReduction>1</mechanicalReduction>
        </actuator>
    </transmission>
    <transmission name="joint_index_MCP_tran">
        <type>transmission_interface/SimpleTransmission</type>
        <joint name="joint_index_MCP">
            <hardwareInterface>hardware_interface/EffortJointInterface</hardwareInterface>
        </joint>
        <actuator name="joint_index_MCP_actr">
            <hardwareInterface>hardware_interface/EffortJointInterface</hardwareInterface>
            <mechanicalReduction>1</mechanicalReduction>
        </actuator>
    </transmission>
    <transmission name="joint_index_PIP_tran">
        <type>transmission_interface/SimpleTransmission</type>
        <joint name="joint_index_PIP">
            <hardwareInterface>hardware_interface/EffortJointInterface</hardwareInterface>
        </joint>
        <actuator name="joint_index_PIP_actr">
            <hardwareInterface>hardware_interface/EffortJointInterface</hardwareInterface>
            <mechanicalReduction>1</mechanicalReduction>
        </actuator>
    </transmission>
    <transmission name="joint_index_DIP_tran">
        <type>transmission_interface/SimpleTransmission</type>
        <joint name="joint_index_DIP">
            <hardwareInterface>hardware_interface/EffortJointInterface</hardwareInterface>
        </joint>
        <actuator name="joint_index_DIP_actr">
            <hardwareInterface>hardware_interface/EffortJointInterface</hardwareInterface>
            <mechanicalReduction>1</mechanicalReduction>
        </actuator>
    </transmission>
    <transmission name="joint_middle_MCP_tran">
        <type>transmission_interface/SimpleTransmission</type>
        <joint name="joint_middle_MCP">
            <hardwareInterface>hardware_interface/EffortJointInterface</hardwareInterface>
        </joint>
        <actuator name="joint_middle_MCP_actr">
            <hardwareInterface>hardware_interface/EffortJointInterface</hardwareInterface>
            <mechanicalReduction>1</mechanicalReduction>
        </actuator>
    </transmission>
    <transmission name="joint_middle_PIP_tran">
        <type>transmission_interface/SimpleTransmission</type>
        <joint name="joint_middle_PIP">
            <hardwareInterface>hardware_interface/EffortJointInterface</hardwareInterface>
        </joint>
        <actuator name="joint_middle_PIP_actr">
            <hardwareInterface>hardware_interface/EffortJointInterface</hardwareInterface>
            <mechanicalReduction>1</mechanicalReduction>
        </actuator>
    </transmission>
    <transmission name="joint_middle_DIP_tran">
        <type>transmission_interface/SimpleTransmission</type>
        <joint name="joint_middle_DIP">
            <hardwareInterface>hardware_interface/EffortJointInterface</hardwareInterface>
        </joint>
        <actuator name="joint_middle_DIP_actr">
            <hardwareInterface>hardware_interface/EffortJointInterface</hardwareInterface>
            <mechanicalReduction>1</mechanicalReduction>
        </actuator>
    </transmission>
    <transmission name="joint_ring_MCP_tran">
        <type>transmission_interface/SimpleTransmission</type>
        <joint name="joint_ring_MCP">
            <hardwareInterface>hardware_interface/EffortJointInterface</hardwareInterface>
        </joint>
        <actuator name="joint_ring_MCP_actr">
            <hardwareInterface>hardware_interface/EffortJointInterface</hardwareInterface>
            <mechanicalReduction>1</mechanicalReduction>
        </actuator>
    </transmission>
    <transmission name="joint_ring_PIP_tran">
        <type>transmission_interface/SimpleTransmission</type>
        <joint name="joint_ring_PIP">
            <hardwareInterface>hardware_interface/EffortJointInterface</hardwareInterface>
        </joint>
        <actuator name="joint_ring_PIP_actr">
            <hardwareInterface>hardware_interface/EffortJointInterface</hardwareInterface>
            <mechanicalReduction>1</mechanicalReduction>
        </actuator>
    </transmission>
    <transmission name="joint_ring_DIP_tran">
        <type>transmission_interface/SimpleTransmission</type>
        <joint name="joint_ring_DIP">
            <hardwareInterface>hardware_interface/EffortJointInterface</hardwareInterface>
        </joint>
        <actuator name="joint_ring_DIP_actr">
            <hardwareInterface>hardware_interface/EffortJointInterface</hardwareInterface>
            <mechanicalReduction>1</mechanicalReduction>
        </actuator>
    </transmission>
    <transmission name="joint_pinky_MCP_tran">
        <type>transmission_interface/SimpleTransmission</type>
        <joint name="joint_pinky_MCP">
            <hardwareInterface>hardware_interface/EffortJointInterface</hardwareInterface>
        </joint>
        <actuator name="joint_pinky_MCP_actr">
            <hardwareInterface>hardware_interface/EffortJointInterface</hardwareInterface>
            <mechanicalReduction>1</mechanicalReduction>
        </actuator>
    </transmission>
    <transmission name="joint_pinky_PIP_tran">
        <type>transmission_interface/SimpleTransmission</type>
        <joint name="joint_pinky_PIP">
            <hardwareInterface>hardware_interface/EffortJointInterface</hardwareInterface>
        </joint>
        <actuator name="joint_pinky_PIP_actr">
            <hardwareInterface>hardware_interface/EffortJointInterface</hardwareInterface>
            <mechanicalReduction>1</mechanicalReduction>
        </actuator>
    </transmission>
    <transmission name="joint_pinky_DIP_tran">
        <type>transmission_interface/SimpleTransmission</type>
        <joint name="joint_pinky_DIP">
            <hardwareInterface>hardware_interface/EffortJointInterface</hardwareInterface>
        </joint>
        <actuator name="joint_pinky_DIP_actr">
            <hardwareInterface>hardware_interface/EffortJointInterface</hardwareInterface>
            <mechanicalReduction>1</mechanicalReduction>
        </actuator>
    </transmission>
    <transmission name="joint_thumb_CMC_1_tran">
        <type>transmission_interface/SimpleTransmission</type>
        <joint name="joint_thumb_CMC_1">
            <hardwareInterface>hardware_interface/EffortJointInterface</hardwareInterface>
        </joint>
        <actuator name="joint_thumb_CMC_1_actr">
            <hardwareInterface>hardware_interface/EffortJointInterface</hardwareInterface>
            <mechanicalReduction>1</mechanicalReduction>
        </actuator>
    </transmission>
    <transmission name="joint_thumb_CMC_2_tran">
        <type>transmission_interface/SimpleTransmission</type>
        <joint name="joint_thumb_CMC_2">
            <hardwareInterface>hardware_interface/EffortJointInterface</hardwareInterface>
        </joint>
        <actuator name="joint_thumb_CMC_2_actr">
            <hardwareInterface>hardware_interface/EffortJointInterface</hardwareInterface>
            <mechanicalReduction>1</mechanicalReduction>
        </actuator>
    </transmission>
    <transmission name="joint_thumb_MP_tran">
        <type>transmission_interface/SimpleTransmission</type>
        <joint name="joint_thumb_MP">
            <hardwareInterface>hardware_interface/EffortJointInterface</hardwareInterface>
        </joint>
        <actuator name="joint_thumb_MP_actr">
            <hardwareInterface>hardware_interface/EffortJointInterface</hardwareInterface>
            <mechanicalReduction>1</mechanicalReduction>
        </actuator>
    </transmission>
    <transmission name="joint_thumb_IP_tran">
        <type>transmission_interface/SimpleTransmission</type>
        <joint name="joint_thumb_IP">
            <hardwareInterface>hardware_interface/EffortJointInterface</hardwareInterface>
        </joint>
        <actuator name="joint_thumb_IP_actr">
            <hardwareInterface>hardware_interface/EffortJointInterface</hardwareInterface>
            <mechanicalReduction>1</mechanicalReduction>
        </actuator>
    </transmission>
    <gazebo>
        <plugin filename="libgazebo_ros_control.so" name="control" />
        <plugin name="gazebo_ros_control" filename="libgazebo_ros_control.so">
            <robotNamespace>/</robotNamespace>
        </plugin>
    </gazebo>
    <gazebo reference="base_link">
        <material>Gazebo/Silver</material>
        <mu1>0.2</mu1>
        <mu2>0.2</mu2>
        <selfCollide>true</selfCollide>
        <gravity>true</gravity>
    </gazebo>
    <gazebo reference="link1_1">
        <material>Gazebo/Silver</material>
        <mu1>0.2</mu1>
        <mu2>0.2</mu2>
        <selfCollide>true</selfCollide>
    </gazebo>
    <gazebo reference="link2_1">
        <material>Gazebo/Silver</material>
        <mu1>0.2</mu1>
        <mu2>0.2</mu2>
        <selfCollide>true</selfCollide>
    </gazebo>
    <gazebo reference="link3_1">
        <material>Gazebo/Silver</material>
        <mu1>0.2</mu1>
        <mu2>0.2</mu2>
        <selfCollide>true</selfCollide>
    </gazebo>
    <gazebo reference="link4_1">
        <material>Gazebo/Silver</material>
        <mu1>0.2</mu1>
        <mu2>0.2</mu2>
        <selfCollide>true</selfCollide>
    </gazebo>
    <gazebo reference="link5_1">
        <material>Gazebo/Silver</material>
        <mu1>0.2</mu1>
        <mu2>0.2</mu2>
        <selfCollide>true</selfCollide>
    </gazebo>
    <gazebo reference="link6_1">
        <material>Gazebo/Silver</material>
        <mu1>0.2</mu1>
        <mu2>0.2</mu2>
        <selfCollide>true</selfCollide>
    </gazebo>
    <gazebo reference="palm_1">
        <material>Gazebo/Silver</material>
        <mu1>0.2</mu1>
        <mu2>0.2</mu2>
        <selfCollide>true</selfCollide>
    </gazebo>
    <gazebo reference="index_1_1">
        <material>Gazebo/Silver</material>
        <mu1>0.2</mu1>
        <mu2>0.2</mu2>
        <selfCollide>true</selfCollide>
    </gazebo>
    <gazebo reference="middle_1_1">
        <material>Gazebo/Silver</material>
        <mu1>0.2</mu1>
        <mu2>0.2</mu2>
        <selfCollide>true</selfCollide>
    </gazebo>
    <gazebo reference="ring_1_1">
        <material>Gazebo/Silver</material>
        <mu1>0.2</mu1>
        <mu2>0.2</mu2>
        <selfCollide>true</selfCollide>
    </gazebo>
    <gazebo reference="pinky_1_1">
        <material>Gazebo/Silver</material>
        <mu1>0.2</mu1>
        <mu2>0.2</mu2>
        <selfCollide>true</selfCollide>
    </gazebo>
    <gazebo reference="index_2_1">
        <material>Gazebo/Silver</material>
        <mu1>0.2</mu1>
        <mu2>0.2</mu2>
        <selfCollide>true</selfCollide>
    </gazebo>
    <gazebo reference="index_3_1">
        <material>Gazebo/Silver</material>
        <mu1>0.2</mu1>
        <mu2>0.2</mu2>
        <selfCollide>true</selfCollide>
    </gazebo>
    <gazebo reference="index_4_1">
        <material>Gazebo/Silver</material>
        <mu1>0.2</mu1>
        <mu2>0.2</mu2>
        <selfCollide>true</selfCollide>
    </gazebo>
    <gazebo reference="middle_2_1">
        <material>Gazebo/Silver</material>
        <mu1>0.2</mu1>
        <mu2>0.2</mu2>
        <selfCollide>true</selfCollide>
    </gazebo>
    <gazebo reference="middle_3_1">
        <material>Gazebo/Silver</material>
        <mu1>0.2</mu1>
        <mu2>0.2</mu2>
        <selfCollide>true</selfCollide>
    </gazebo>
    <gazebo reference="middle_4_1">
        <material>Gazebo/Silver</material>
        <mu1>0.2</mu1>
        <mu2>0.2</mu2>
        <selfCollide>true</selfCollide>
    </gazebo>
    <gazebo reference="ring_2_1">
        <material>Gazebo/Silver</material>
        <mu1>0.2</mu1>
        <mu2>0.2</mu2>
        <selfCollide>true</selfCollide>
    </gazebo>
    <gazebo reference="ring_3_1">
        <material>Gazebo/Silver</material>
        <mu1>0.2</mu1>
        <mu2>0.2</mu2>
        <selfCollide>true</selfCollide>
    </gazebo>
    <gazebo reference="ring_4_1">
        <material>Gazebo/Silver</material>
        <mu1>0.2</mu1>
        <mu2>0.2</mu2>
        <selfCollide>true</selfCollide>
    </gazebo>
    <gazebo reference="pinky_2_1">
        <material>Gazebo/Silver</material>
        <mu1>0.2</mu1>
        <mu2>0.2</mu2>
        <selfCollide>true</selfCollide>
    </gazebo>
    <gazebo reference="pinky_3_1">
        <material>Gazebo/Silver</material>
        <mu1>0.2</mu1>
        <mu2>0.2</mu2>
        <selfCollide>true</selfCollide>
    </gazebo>
    <gazebo reference="pinky_4_1">
        <material>Gazebo/Silver</material>
        <mu1>0.2</mu1>
        <mu2>0.2</mu2>
        <selfCollide>true</selfCollide>
    </gazebo>
    <gazebo reference="thumb_1_1">
        <material>Gazebo/Silver</material>
        <mu1>0.2</mu1>
        <mu2>0.2</mu2>
        <selfCollide>true</selfCollide>
    </gazebo>
    <gazebo reference="thumb_2_1">
        <material>Gazebo/Silver</material>
        <mu1>0.2</mu1>
        <mu2>0.2</mu2>
        <selfCollide>true</selfCollide>
    </gazebo>
    <gazebo reference="thumb_3_1">
        <material>Gazebo/Silver</material>
        <mu1>0.2</mu1>
        <mu2>0.2</mu2>
        <selfCollide>true</selfCollide>
    </gazebo>
    <gazebo reference="thumb_4_1">
        <material>Gazebo/Silver</material>
        <mu1>0.2</mu1>
        <mu2>0.2</mu2>
        <selfCollide>true</selfCollide>
    </gazebo>
    <link name="base_link">
        <inertial>
            <origin rpy="0 0 0" xyz="0.001253595501875241 -2.425128974916387e-16 0.016880943454350202" />
            <mass value="9.000971366531325" />
            <inertia ixx="0.010003" ixy="0.0" ixz="3e-05" iyy="0.009958" iyz="-0.0" izz="0.017765" />
        </inertial>
        <visual>
            <origin rpy="0 0 0" xyz="0 0 0" />
            <geometry>
                <mesh filename="package://mk_description/meshes/base_link.stl" scale="0.001 0.001 0.001" />
            </geometry>
            <material name="silver" />
        </visual>
        <collision>
            <origin rpy="0 0 0" xyz="0 0 0" />
            <geometry>
                <mesh filename="package://mk_description/meshes/base_link.stl" scale="0.001 0.001 0.001" />
            </geometry>
        </collision>
    </link>
    <link name="link1_1">
        <inertial>
            <origin rpy="0 0 0" xyz="0.012757531934532012 1.2186053422867295e-12 0.06719265641075811" />
            <mass value="0.00001" />
            <inertia ixx="0.011232" ixy="0.0" ixz="-0.001286" iyy="0.011123" iyz="0.0" izz="0.009013" />
        </inertial>
        <visual>
            <origin rpy="0 0 0" xyz="-0.0 -0.0 -0.061" />
            <geometry>
                <mesh filename="package://mk_description/meshes/link1_1.stl" scale="0.001 0.001 0.001" />
            </geometry>
            <material name="silver" />
        </visual>
        <collision>
            <origin rpy="0 0 0" xyz="-0.0 -0.0 -0.061" />
            <geometry>
                <mesh filename="package://mk_description/meshes/link1_1.stl" scale="0.001 0.001 0.001" />
            </geometry>
        </collision>
    </link>
    <link name="link2_1">
        <inertial>
            <origin rpy="0 0 0" xyz="0.07202168862575391 -3.5313984794949443e-12 0.1445001916818219" />
            <mass value="0.00001" />
            <inertia ixx="0.132567" ixy="-0.0" ixz="-0.007531" iyy="0.13402" iyz="-0.0" izz="0.029131" />
        </inertial>
        <visual>
            <origin rpy="0 0 0" xyz="-0.071 -0.0 -0.151" />
            <geometry>
                <mesh filename="package://mk_description/meshes/link2_1.stl" scale="0.001 0.001 0.001" />
            </geometry>
            <material name="silver" />
        </visual>
        <collision>
            <origin rpy="0 0 0" xyz="-0.071 -0.0 -0.151" />
            <geometry>
                <mesh filename="package://mk_description/meshes/link2_1.stl" scale="0.001 0.001 0.001" />
            </geometry>
        </collision>
    </link>
    <link name="link3_1">
        <inertial>
            <origin rpy="0 0 0" xyz="-0.05114273870375564 4.038438904121806e-13 0.014758066823390759" />
            <mass value="0.00001" />
            <inertia ixx="0.003791" ixy="0.0" ixz="0.000672" iyy="0.004814" iyz="-0.0" izz="0.004679" />
        </inertial>
        <visual>
            <origin rpy="0 0 0" xyz="-0.09 0.0 -0.461" />
            <geometry>
                <mesh filename="package://mk_description/meshes/link3_1.stl" scale="0.001 0.001 0.001" />
            </geometry>
            <material name="silver" />
        </visual>
        <collision>
            <origin rpy="0 0 0" xyz="-0.09 0.0 -0.461" />
            <geometry>
                <mesh filename="package://mk_description/meshes/link3_1.stl" scale="0.001 0.001 0.001" />
            </geometry>
        </collision>
    </link>
    <link name="link4_1">
        <inertial>
            <origin rpy="0 0 0" xyz="0.002693323451248456 3.8855923684264276e-08 0.08440714552064266" />
            <mass value="0.00001" />
            <inertia ixx="0.033994" ixy="-0.0" ixz="-0.003025" iyy="0.034351" iyz="-0.0" izz="0.010735" />
        </inertial>
        <visual>
            <origin rpy="0 0 0" xyz="-0.02 -0.0 -0.517" />
            <geometry>
                <mesh filename="package://mk_description/meshes/link4_1.stl" scale="0.001 0.001 0.001" />
            </geometry>
            <material name="silver" />
        </visual>
        <collision>
            <origin rpy="0 0 0" xyz="-0.02 -0.0 -0.517" />
            <geometry>
                <mesh filename="package://mk_description/meshes/link4_1.stl" scale="0.001 0.001 0.001" />
            </geometry>
        </collision>
    </link>
    <link name="link5_1">
        <inertial>
            <origin rpy="0 0 0" xyz="0.0559602537349705 -2.0965830206548403e-07 0.016043221095647042" />
            <mass value="0.00001" />
            <inertia ixx="0.002409" ixy="0.0" ixz="-0.000572" iyy="0.003275" iyz="0.0" izz="0.003165" />
        </inertial>
        <visual>
            <origin rpy="0 0 0" xyz="-0.0735 -0.0 -0.721" />
            <geometry>
                <mesh filename="package://mk_description/meshes/link5_1.stl" scale="0.001 0.001 0.001" />
            </geometry>
            <material name="silver" />
        </visual>
        <collision>
            <origin rpy="0 0 0" xyz="-0.0735 -0.0 -0.721" />
            <geometry>
                <mesh filename="package://mk_description/meshes/link5_1.stl" scale="0.001 0.001 0.001" />
            </geometry>
        </collision>
    </link>
    <link name="link6_1">
        <inertial>
            <origin rpy="0 0 0" xyz="0.00010433437375184651 -0.005286826016069605 0.07445480614360678" />
            <mass value="0.00001" />
            <inertia ixx="0.004651" ixy="-1e-06" ixz="6e-06" iyy="0.004904" iyz="2.6e-05" izz="0.001868" />
        </inertial>
        <visual>
            <origin rpy="0 0 0" xyz="-0.1485 -0.0 -0.7745" />
            <geometry>
                <mesh filename="package://mk_description/meshes/link6_1.stl" scale="0.001 0.001 0.001" />
            </geometry>
            <material name="silver" />
        </visual>
        <collision>
            <origin rpy="0 0 0" xyz="-0.1485 -0.0 -0.7745" />
            <geometry>
                <mesh filename="package://mk_description/meshes/link6_1.stl" scale="0.001 0.001 0.001" />
            </geometry>
        </collision>
    </link>
    <link name="palm_1">
        <inertial>
            <origin rpy="0 0 0" xyz="-0.01849799368570129 -0.003288621708244126 0.05472215474509601" />
            <mass value="0.00001" />
            <inertia ixx="0.004173" ixy="-3.9e-05" ixz="0.000254" iyy="0.002907" iyz="0.000149" izz="0.001986" />
        </inertial>
        <visual>
            <origin rpy="0 0 0" xyz="-0.1485 -0.0 -0.9245" />
            <geometry>
                <mesh filename="package://mk_description/meshes/palm_1.stl" scale="0.001 0.001 0.001" />
            </geometry>
            <material name="silver" />
        </visual>
        <collision>
            <origin rpy="0 0 0" xyz="-0.1485 -0.0 -0.9245" />
            <geometry>
                <mesh filename="package://mk_description/meshes/palm_1.stl" scale="0.001 0.001 0.001" />
            </geometry>
        </collision>
    </link>
    <link name="index_1_1">
        <inertial>
            <origin rpy="0 0 0" xyz="-0.012003156274217913 -0.0001843174038660758 0.015503517151384427" />
            <mass value="0.00001" />
            <inertia ixx="7e-06" ixy="1e-06" ixz="-0.0" iyy="1e-05" iyz="1e-06" izz="8e-06" />
        </inertial>
        <visual>
            <origin rpy="0 0 0" xyz="-0.143105 -0.038906 -1.029721" />
            <geometry>
                <mesh filename="package://mk_description/meshes/index_1_1.stl" scale="0.001 0.001 0.001" />
            </geometry>
            <material name="silver" />
        </visual>
        <collision>
            <origin rpy="0 0 0" xyz="-0.143105 -0.038906 -1.029721" />
            <geometry>
                <mesh filename="package://mk_description/meshes/index_1_1.stl" scale="0.001 0.001 0.001" />
            </geometry>
        </collision>
    </link>
    <link name="middle_1_1">
        <inertial>
            <origin rpy="0 0 0" xyz="-0.011873129755786943 -0.003344684606072878 0.015242306952340856" />
            <mass value="0.00001" />
            <inertia ixx="7e-06" ixy="1e-06" ixz="-0.0" iyy="9e-06" iyz="1e-06" izz="8e-06" />
        </inertial>
        <visual>
            <origin rpy="0 0 0" xyz="-0.142823 -0.007655 -1.033686" />
            <geometry>
                <mesh filename="package://mk_description/meshes/middle_1_1.stl" scale="0.001 0.001 0.001" />
            </geometry>
            <material name="silver" />
        </visual>
        <collision>
            <origin rpy="0 0 0" xyz="-0.142823 -0.007655 -1.033686" />
            <geometry>
                <mesh filename="package://mk_description/meshes/middle_1_1.stl" scale="0.001 0.001 0.001" />
            </geometry>
        </collision>
    </link>
    <link name="ring_1_1">
        <inertial>
            <origin rpy="0 0 0" xyz="-0.01177642870038545 -0.006392943751630707 0.01431467736832781" />
            <mass value="0.00001" />
            <inertia ixx="7e-06" ixy="1e-06" ixz="-0.0" iyy="9e-06" iyz="2e-06" izz="9e-06" />
        </inertial>
        <visual>
            <origin rpy="0 0 0" xyz="-0.14332 0.0242 -1.031634" />
            <geometry>
                <mesh filename="package://mk_description/meshes/ring_1_1.stl" scale="0.001 0.001 0.001" />
            </geometry>
            <material name="silver" />
        </visual>
        <collision>
            <origin rpy="0 0 0" xyz="-0.14332 0.0242 -1.031634" />
            <geometry>
                <mesh filename="package://mk_description/meshes/ring_1_1.stl" scale="0.001 0.001 0.001" />
            </geometry>
        </collision>
    </link>
    <link name="pinky_1_1">
        <inertial>
            <origin rpy="0 0 0" xyz="-0.011710261878068423 -0.00918021492423643 0.01276899388554198" />
            <mass value="0.00001" />
            <inertia ixx="7e-06" ixy="1e-06" ixz="-0.0" iyy="8e-06" iyz="1e-06" izz="9e-06" />
        </inertial>
        <visual>
            <origin rpy="0 0 0" xyz="-0.144438 0.053842 -1.022516" />
            <geometry>
                <mesh filename="package://mk_description/meshes/pinky_1_1.stl" scale="0.001 0.001 0.001" />
            </geometry>
            <material name="silver" />
        </visual>
        <collision>
            <origin rpy="0 0 0" xyz="-0.144438 0.053842 -1.022516" />
            <geometry>
                <mesh filename="package://mk_description/meshes/pinky_1_1.stl" scale="0.001 0.001 0.001" />
            </geometry>
        </collision>
    </link>
    <link name="index_2_1">
        <inertial>
            <origin rpy="0 0 0" xyz="0.0013592426070857533 0.014112910707545577 0.006584417463850301" />
            <mass value="0.00001" />
            <inertia ixx="2.4e-05" ixy="-0.0" ixz="-1e-06" iyy="2.2e-05" iyz="1e-06" izz="1.1e-05" />
        </inertial>
        <visual>
            <origin rpy="0 0 0" xyz="-0.13696 -0.030659 -1.064498" />
            <geometry>
                <mesh filename="package://mk_description/meshes/index_2_1.stl" scale="0.001 0.001 0.001" />
            </geometry>
            <material name="silver" />
        </visual>
        <collision>
            <origin rpy="0 0 0" xyz="-0.13696 -0.030659 -1.064498" />
            <geometry>
                <mesh filename="package://mk_description/meshes/index_2_1.stl" scale="0.001 0.001 0.001" />
            </geometry>
        </collision>
    </link>
    <link name="index_3_1">
        <inertial>
            <origin rpy="0 0 0" xyz="0.001359142984049877 0.014112479821706991 0.006584419644577233" />
            <mass value="0.00001" />
            <inertia ixx="2.4e-05" ixy="-0.0" ixz="-1e-06" iyy="2.2e-05" iyz="1e-06" izz="1.1e-05" />
        </inertial>
        <visual>
            <origin rpy="0 0 0" xyz="-0.140923 -0.037336 -1.102207" />
            <geometry>
                <mesh filename="package://mk_description/meshes/index_3_1.stl" scale="0.001 0.001 0.001" />
            </geometry>
            <material name="silver" />
        </visual>
        <collision>
            <origin rpy="0 0 0" xyz="-0.140923 -0.037336 -1.102207" />
            <geometry>
                <mesh filename="package://mk_description/meshes/index_3_1.stl" scale="0.001 0.001 0.001" />
            </geometry>
        </collision>
    </link>
    <link name="index_4_1">
        <inertial>
            <origin rpy="0 0 0" xyz="0.0012067405325764669 0.014773830435752318 0.0046425218728198825" />
            <mass value="0.00001" />
            <inertia ixx="1.7e-05" ixy="-0.0" ixz="-1e-06" iyy="1.5e-05" iyz="-1e-06" izz="1e-05" />
        </inertial>
        <visual>
            <origin rpy="0 0 0" xyz="-0.144886 -0.044012 -1.139916" />
            <geometry>
                <mesh filename="package://mk_description/meshes/index_4_1.stl" scale="0.001 0.001 0.001" />
            </geometry>
            <material name="silver" />
        </visual>
        <collision>
            <origin rpy="0 0 0" xyz="-0.144886 -0.044012 -1.139916" />
            <geometry>
                <mesh filename="package://mk_description/meshes/index_4_1.stl" scale="0.001 0.001 0.001" />
            </geometry>
        </collision>
    </link>
    <link name="middle_2_1">
        <inertial>
            <origin rpy="0 0 0" xyz="0.0009410365815004373 0.012755743075373938 0.008986834760588147" />
            <mass value="0.00001" />
            <inertia ixx="2.4e-05" ixy="0.0" ixz="-1e-06" iyy="2.1e-05" iyz="2e-06" izz="1.1e-05" />
        </inertial>
        <visual>
            <origin rpy="0 0 0" xyz="-0.137217 0.006845 -1.066452" />
            <geometry>
                <mesh filename="package://mk_description/meshes/middle_2_1.stl" scale="0.001 0.001 0.001" />
            </geometry>
            <material name="silver" />
        </visual>
        <collision>
            <origin rpy="0 0 0" xyz="-0.137217 0.006845 -1.066452" />
            <geometry>
                <mesh filename="package://mk_description/meshes/middle_2_1.stl" scale="0.001 0.001 0.001" />
            </geometry>
        </collision>
    </link>
    <link name="middle_3_1">
        <inertial>
            <origin rpy="0 0 0" xyz="0.0009403824173050968 0.012755743075381711 0.008986927732266725" />
            <mass value="0.00001" />
            <inertia ixx="2.4e-05" ixy="0.0" ixz="-1e-06" iyy="2.1e-05" iyz="2e-06" izz="1.1e-05" />
        </inertial>
        <visual>
            <origin rpy="0 0 0" xyz="-0.141242 0.006845 -1.104741" />
            <geometry>
                <mesh filename="package://mk_description/meshes/middle_3_1.stl" scale="0.001 0.001 0.001" />
            </geometry>
            <material name="silver" />
        </visual>
        <collision>
            <origin rpy="0 0 0" xyz="-0.141242 0.006845 -1.104741" />
            <geometry>
                <mesh filename="package://mk_description/meshes/middle_3_1.stl" scale="0.001 0.001 0.001" />
            </geometry>
        </collision>
    </link>
    <link name="middle_4_1">
        <inertial>
            <origin rpy="0 0 0" xyz="0.0007519472486991197 0.013745528207874521 0.007193841713581728" />
            <mass value="0.00001" />
            <inertia ixx="1.7e-05" ixy="-0.0" ixz="-1e-06" iyy="1.5e-05" iyz="-0.0" izz="9e-06" />
        </inertial>
        <visual>
            <origin rpy="0 0 0" xyz="-0.145266 0.006845 -1.14303" />
            <geometry>
                <mesh filename="package://mk_description/meshes/middle_4_1.stl" scale="0.001 0.001 0.001" />
            </geometry>
            <material name="silver" />
        </visual>
        <collision>
            <origin rpy="0 0 0" xyz="-0.145266 0.006845 -1.14303" />
            <geometry>
                <mesh filename="package://mk_description/meshes/middle_4_1.stl" scale="0.001 0.001 0.001" />
            </geometry>
        </collision>
    </link>
    <link name="ring_2_1">
        <inertial>
            <origin rpy="0 0 0" xyz="0.0004933103936223815 0.010978865647973998 0.01111737284077896" />
            <mass value="0.00001" />
            <inertia ixx="2.4e-05" ixy="1e-06" ixz="-1e-06" iyy="2e-05" iyz="4e-06" izz="1.2e-05" />
        </inertial>
        <visual>
            <origin rpy="0 0 0" xyz="-0.138159 0.044474 -1.061258" />
            <geometry>
                <mesh filename="package://mk_description/meshes/ring_2_1.stl" scale="0.001 0.001 0.001" />
            </geometry>
            <material name="silver" />
        </visual>
        <collision>
            <origin rpy="0 0 0" xyz="-0.138159 0.044474 -1.061258" />
            <geometry>
                <mesh filename="package://mk_description/meshes/ring_2_1.stl" scale="0.001 0.001 0.001" />
            </geometry>
        </collision>
    </link>
    <link name="ring_3_1">
        <inertial>
            <origin rpy="0 0 0" xyz="0.0004932107705865052 0.010978296533827897 0.011117375021508336" />
            <mass value="0.00001" />
            <inertia ixx="2.4e-05" ixy="1e-06" ixz="-1e-06" iyy="2e-05" iyz="4e-06" izz="1.2e-05" />
        </inertial>
        <visual>
            <origin rpy="0 0 0" xyz="-0.142122 0.05115 -1.098967" />
            <geometry>
                <mesh filename="package://mk_description/meshes/ring_3_1.stl" scale="0.001 0.001 0.001" />
            </geometry>
            <material name="silver" />
        </visual>
        <collision>
            <origin rpy="0 0 0" xyz="-0.142122 0.05115 -1.098967" />
            <geometry>
                <mesh filename="package://mk_description/meshes/ring_3_1.stl" scale="0.001 0.001 0.001" />
            </geometry>
        </collision>
    </link>
    <link name="ring_4_1">
        <inertial>
            <origin rpy="0 0 0" xyz="0.00027360763069000926 0.012264850963387482 0.0095272488413789" />
            <mass value="0.00001" />
            <inertia ixx="1.7e-05" ixy="0.0" ixz="-1e-06" iyy="1.5e-05" iyz="1e-06" izz="9e-06" />
        </inertial>
        <visual>
            <origin rpy="0 0 0" xyz="-0.146085 0.057827 -1.136676" />
            <geometry>
                <mesh filename="package://mk_description/meshes/ring_4_1.stl" scale="0.001 0.001 0.001" />
            </geometry>
            <material name="silver" />
        </visual>
        <collision>
            <origin rpy="0 0 0" xyz="-0.146085 0.057827 -1.136676" />
            <geometry>
                <mesh filename="package://mk_description/meshes/ring_4_1.stl" scale="0.001 0.001 0.001" />
            </geometry>
        </collision>
    </link>
    <link name="pinky_2_1">
        <inertial>
            <origin rpy="0 0 0" xyz="2.2107880944283176e-05 0.008666033434462497 0.012814334487809775" />
            <mass value="0.00001" />
            <inertia ixx="2.4e-05" ixy="1e-06" ixz="-1e-06" iyy="1.8e-05" iyz="5e-06" izz="1.4e-05" />
        </inertial>
        <visual>
            <origin rpy="0 0 0" xyz="-0.139636 0.079177 -1.048017" />
            <geometry>
                <mesh filename="package://mk_description/meshes/pinky_2_1.stl" scale="0.001 0.001 0.001" />
            </geometry>
            <material name="silver" />
        </visual>
        <collision>
            <origin rpy="0 0 0" xyz="-0.139636 0.079177 -1.048017" />
            <geometry>
                <mesh filename="package://mk_description/meshes/pinky_2_1.stl" scale="0.001 0.001 0.001" />
            </geometry>
        </collision>
    </link>
    <link name="pinky_3_1">
        <inertial>
            <origin rpy="0 0 0" xyz="8.091020338218957e-06 0.008852933732520829 0.012884042204742041" />
            <mass value="0.00001" />
            <inertia ixx="2.4e-05" ixy="1e-06" ixz="-1e-06" iyy="1.8e-05" iyz="5e-06" izz="1.4e-05" />
        </inertial>
        <visual>
            <origin rpy="0 0 0" xyz="-0.143427 0.092468 -1.083951" />
            <geometry>
                <mesh filename="package://mk_description/meshes/pinky_3_1.stl" scale="0.001 0.001 0.001" />
            </geometry>
            <material name="silver" />
        </visual>
        <collision>
            <origin rpy="0 0 0" xyz="-0.143427 0.092468 -1.083951" />
            <geometry>
                <mesh filename="package://mk_description/meshes/pinky_3_1.stl" scale="0.001 0.001 0.001" />
            </geometry>
        </collision>
    </link>
    <link name="pinky_4_1">
        <inertial>
            <origin rpy="0 0 0" xyz="-0.00023699550517802814 0.010392110335995783 0.01154159751508299" />
            <mass value="0.00001" />
            <inertia ixx="1.7e-05" ixy="0.0" ixz="-1e-06" iyy="1.5e-05" iyz="2e-06" izz="1e-05" />
        </inertial>
        <visual>
            <origin rpy="0 0 0" xyz="-0.147204 0.105572 -1.119955" />
            <geometry>
                <mesh filename="package://mk_description/meshes/pinky_4_1.stl" scale="0.001 0.001 0.001" />
            </geometry>
            <material name="silver" />
        </visual>
        <collision>
            <origin rpy="0 0 0" xyz="-0.147204 0.105572 -1.119955" />
            <geometry>
                <mesh filename="package://mk_description/meshes/pinky_4_1.stl" scale="0.001 0.001 0.001" />
            </geometry>
        </collision>
    </link>
    <link name="thumb_1_1">
        <inertial>
            <origin rpy="0 0 0" xyz="0.0033442043857143666 0.01920624215067031 -0.008254977053352541" />
            <mass value="0.00001" />
            <inertia ixx="9e-06" ixy="-2e-06" ixz="-0.0" iyy="8e-06" iyz="1e-06" izz="8e-06" />
        </inertial>
        <visual>
            <origin rpy="0 0 0" xyz="-0.15275 -0.011386 -0.962857" />
            <geometry>
                <mesh filename="package://mk_description/meshes/thumb_1_1.stl" scale="0.001 0.001 0.001" />
            </geometry>
            <material name="silver" />
        </visual>
        <collision>
            <origin rpy="0 0 0" xyz="-0.15275 -0.011386 -0.962857" />
            <geometry>
                <mesh filename="package://mk_description/meshes/thumb_1_1.stl" scale="0.001 0.001 0.001" />
            </geometry>
        </collision>
    </link>
    <link name="thumb_2_1">
        <inertial>
            <origin rpy="0 0 0" xyz="-0.012756223295727287 0.008187679826243473 0.003822349671507075" />
            <mass value="0.00001" />
            <inertia ixx="2.1e-05" ixy="-2e-06" ixz="-1e-06" iyy="1.3e-05" iyz="-5e-06" izz="2.2e-05" />
        </inertial>
        <visual>
            <origin rpy="0 0 0" xyz="-0.16725 -0.048841 -0.958255" />
            <geometry>
                <mesh filename="package://mk_description/meshes/thumb_2_1.stl" scale="0.001 0.001 0.001" />
            </geometry>
            <material name="silver" />
        </visual>
        <collision>
            <origin rpy="0 0 0" xyz="-0.16725 -0.048841 -0.958255" />
            <geometry>
                <mesh filename="package://mk_description/meshes/thumb_2_1.stl" scale="0.001 0.001 0.001" />
            </geometry>
        </collision>
    </link>
    <link name="thumb_3_1">
        <inertial>
            <origin rpy="0 0 0" xyz="-0.012756223295727565 0.0081875296271577 0.0038221527485170492" />
            <mass value="0.00001" />
            <inertia ixx="2.1e-05" ixy="-2e-06" ixz="-1e-06" iyy="1.3e-05" iyz="-5e-06" izz="2.2e-05" />
        </inertial>
        <visual>
            <origin rpy="0 0 0" xyz="-0.16725 -0.083734 -0.974526" />
            <geometry>
                <mesh filename="package://mk_description/meshes/thumb_3_1.stl" scale="0.001 0.001 0.001" />
            </geometry>
            <material name="silver" />
        </visual>
        <collision>
            <origin rpy="0 0 0" xyz="-0.16725 -0.083734 -0.974526" />
            <geometry>
                <mesh filename="package://mk_description/meshes/thumb_3_1.stl" scale="0.001 0.001 0.001" />
            </geometry>
        </collision>
    </link>
    <link name="thumb_4_1">
        <inertial>
            <origin rpy="0 0 0" xyz="-0.013746008428213302 0.006554095628134901 0.00306021727433603" />
            <mass value="0.00001" />
            <inertia ixx="1.5e-05" ixy="0.0" ixz="0.0" iyy="1.1e-05" iyz="-3e-06" izz="1.6e-05" />
        </inertial>
        <visual>
            <origin rpy="0 0 0" xyz="-0.16725 -0.118626 -0.990797" />
            <geometry>
                <mesh filename="package://mk_description/meshes/thumb_4_1.stl" scale="0.001 0.001 0.001" />
            </geometry>
            <material name="silver" />
        </visual>
        <collision>
            <origin rpy="0 0 0" xyz="-0.16725 -0.118626 -0.990797" />
            <geometry>
                <mesh filename="package://mk_description/meshes/thumb_4_1.stl" scale="0.001 0.001 0.001" />
            </geometry>
        </collision>
    </link>
    <joint name="joint1" type="continuous">
        <origin rpy="0 0 0" xyz="0.0 0.0 0.061" />
        <parent link="base_link" />
        <child link="link1_1" />
        <axis xyz="0.0 0.0 1.0" />
        <dynamics damping="1.0" friction="1.0" />
    </joint>
    <joint name="joint2" type="continuous">
        <origin rpy="0 0 0" xyz="0.071 0.0 0.09" />
        <parent link="link1_1" />
        <child link="link2_1" />
        <axis xyz="-1.0 -0.0 -0.0" />
        <dynamics damping="1.0" friction="1.0" />
    </joint>
    <joint name="joint3" type="continuous">
        <origin rpy="0 0 0" xyz="0.019 -0.0 0.31" />
        <parent link="link2_1" />
        <child link="link3_1" />
        <axis xyz="1.0 -0.0 0.0" />
        <dynamics damping="1.0" friction="1.0" />
    </joint>
    <joint name="joint4" type="continuous">
        <origin rpy="0 0 0" xyz="-0.07 0.0 0.056" />
        <parent link="link3_1" />
        <child link="link4_1" />
        <axis xyz="0.0 -0.0 -1.0" />
        <dynamics damping="1.0" friction="1.0" />
    </joint>
    <joint name="joint5" type="continuous">
        <origin rpy="0 0 0" xyz="0.0535 0.0 0.204" />
        <parent link="link4_1" />
        <child link="link5_1" />
        <axis xyz="-1.0 0.0 0.0" />
        <dynamics damping="1.0" friction="1.0" />
    </joint>
    <joint name="joint6" type="continuous">
        <origin rpy="0 0 0" xyz="0.075 0.0 0.0535" />
        <parent link="link5_1" />
        <child link="link6_1" />
        <axis xyz="-0.0 0.0 -1.0" />
        <dynamics damping="1.0" friction="1.0" />
    </joint>
    <joint name="fixed_hand_link6" type="fixed">
        <origin rpy="0 0 0" xyz="0.0 0.0 0.15" />
        <parent link="link6_1" />
        <child link="palm_1" />
    </joint>
    <joint name="joint_index_RT" type="continuous">
        <origin rpy="0 0 0" xyz="-0.005395 0.038906 0.105221" />
        <parent link="palm_1" />
        <child link="index_1_1" />
        <axis xyz="-0.994109 0.051541 0.095347" />
        <dynamics damping="1.0" friction="1.0" />
    </joint>
    <joint name="joint_middle_RT" type="continuous">
        <origin rpy="0 0 0" xyz="-0.005677 0.007655 0.109186" />
        <parent link="palm_1" />
        <child link="middle_1_1" />
        <axis xyz="-0.994522 0.0 0.104528" />
        <dynamics damping="1.0" friction="1.0" />
    </joint>
    <joint name="joint_ring_RT" type="continuous">
        <origin rpy="0 0 0" xyz="-0.00518 -0.0242 0.107134" />
        <parent link="palm_1" />
        <child link="ring_1_1" />
        <axis xyz="-0.994109 -0.051541 0.095347" />
        <dynamics damping="1.0" friction="1.0" />
    </joint>
    <joint name="joint_pinky_RT" type="continuous">
        <origin rpy="0 0 0" xyz="-0.004062 -0.053842 0.098016" />
        <parent link="palm_1" />
        <child link="pinky_1_1" />
        <axis xyz="-0.992811 -0.098225 0.068401" />
        <dynamics damping="1.0" friction="1.0" />
    </joint>
    <joint name="joint_index_MCP" type="continuous">
        <origin rpy="0 0 0" xyz="-0.006145 -0.008247 0.034777" />
        <parent link="index_1_1" />
        <child link="index_2_1" />
        <axis xyz="0.033947 0.983499 -0.177701" />
        <dynamics damping="1.0" friction="1.0" />
    </joint>
    <joint name="joint_index_PIP" type="continuous">
        <origin rpy="0 0 0" xyz="0.003963 0.006677 0.037709" />
        <parent link="index_2_1" />
        <child link="index_3_1" />
        <axis xyz="0.033947 0.983499 -0.177701" />
        <dynamics damping="1.0" friction="1.0" />
    </joint>
    <joint name="joint_index_DIP" type="continuous">
        <origin rpy="0 0 0" xyz="0.003963 0.006676 0.037709" />
        <parent link="index_3_1" />
        <child link="index_4_1" />
        <axis xyz="0.033947 0.983499 -0.177701" />
        <dynamics damping="1.0" friction="1.0" />
    </joint>
    <joint name="joint_middle_MCP" type="continuous">
        <origin rpy="0 0 0" xyz="-0.005606 -0.0145 0.032766" />
        <parent link="middle_1_1" />
        <child link="middle_2_1" />
        <axis xyz="-0.0 1.0 -0.0" />
        <dynamics damping="1.0" friction="1.0" />
    </joint>
    <joint name="joint_middle_PIP" type="continuous">
        <origin rpy="0 0 0" xyz="0.004025 0.0 0.038289" />
        <parent link="middle_2_1" />
        <child link="middle_3_1" />
        <axis xyz="-0.0 1.0 -0.0" />
        <dynamics damping="1.0" friction="1.0" />
    </joint>
    <joint name="joint_middle_DIP" type="continuous">
        <origin rpy="0 0 0" xyz="0.004024 0.0 0.038289" />
        <parent link="middle_3_1" />
        <child link="middle_4_1" />
        <axis xyz="-0.0 1.0 -0.0" />
        <dynamics damping="1.0" friction="1.0" />
    </joint>
    <joint name="joint_ring_MCP" type="continuous">
        <origin rpy="0 0 0" xyz="-0.005161 -0.020274 0.029624" />
        <parent link="ring_1_1" />
        <child link="ring_2_1" />
        <axis xyz="-0.033947 0.983499 0.177701" />
        <dynamics damping="1.0" friction="1.0" />
    </joint>
    <joint name="joint_ring_PIP" type="continuous">
        <origin rpy="0 0 0" xyz="0.003963 -0.006676 0.037709" />
        <parent link="ring_2_1" />
        <child link="ring_3_1" />
        <axis xyz="-0.033947 0.983499 0.177701" />
        <dynamics damping="1.0" friction="1.0" />
    </joint>
    <joint name="joint_ring_DIP" type="continuous">
        <origin rpy="0 0 0" xyz="0.003963 -0.006677 0.037709" />
        <parent link="ring_3_1" />
        <child link="ring_4_1" />
        <axis xyz="-0.033947 0.983499 0.177701" />
        <dynamics damping="1.0" friction="1.0" />
    </joint>
    <joint name="joint_pinky_MCP" type="continuous">
        <origin rpy="0 0 0" xyz="-0.004802 -0.025335 0.025501" />
        <parent link="pinky_1_1" />
        <child link="pinky_2_1" />
        <axis xyz="-0.068575 0.935149 0.347555" />
        <dynamics damping="1.0" friction="1.0" />
    </joint>
    <joint name="joint_pinky_PIP" type="continuous">
        <origin rpy="0 0 0" xyz="0.003791 -0.013291 0.035934" />
        <parent link="pinky_2_1" />
        <child link="pinky_3_1" />
        <axis xyz="-0.068575 0.935149 0.347555" />
        <dynamics damping="1.0" friction="1.0" />
    </joint>
    <joint name="joint_pinky_DIP" type="continuous">
        <origin rpy="0 0 0" xyz="0.003777 -0.013104 0.036004" />
        <parent link="pinky_3_1" />
        <child link="pinky_4_1" />
        <axis xyz="-0.068575 0.935149 0.347555" />
        <dynamics damping="1.0" friction="1.0" />
    </joint>
    <joint name="joint_thumb_CMC_1" type="continuous">
        <origin rpy="0 0 0" xyz="0.00425 0.011386 0.038357" />
        <parent link="palm_1" />
        <child link="thumb_1_1" />
        <axis xyz="-0.0 0.422618 -0.906308" />
        <dynamics damping="1.0" friction="1.0" />
    </joint>
    <joint name="joint_thumb_CMC_2" type="continuous">
        <origin rpy="0 0 0" xyz="0.0145 0.037455 -0.004602" />
        <parent link="thumb_1_1" />
        <child link="thumb_2_1" />
        <axis xyz="-1.0 -0.0 -0.0" />
        <dynamics damping="1.0" friction="1.0" />
    </joint>
    <joint name="joint_thumb_MP" type="continuous">
        <origin rpy="0 0 0" xyz="0.0 0.034893 0.016271" />
        <parent link="thumb_2_1" />
        <child link="thumb_3_1" />
        <axis xyz="-1.0 -0.0 -0.0" />
        <dynamics damping="1.0" friction="1.0" />
    </joint>
    <joint name="joint_thumb_IP" type="continuous">
        <origin rpy="0 0 0" xyz="0.0 0.034892 0.016271" />
        <parent link="thumb_3_1" />
        <child link="thumb_4_1" />
        <axis xyz="-1.0 -0.0 -0.0" />
        <dynamics damping="1.0" friction="1.0" />
    </joint>
    <link name="world" />
    <joint name="world_joint" type="fixed">
        <origin rpy="0 0 0" xyz="0 0 0" />
        <parent link="world" />
        <child link="base_link" />
    </joint>


</robot>

